<?xml version="1.0" ?>
<!-- =================================================================================== -->
<!-- |    This document was autogenerated by xacro from /home/meka/mekabot/M3_IQ/meka-ros/trunk/meka_common/meka_description/robots/meka.urdf.xacro | -->
<!-- |    EDITING THIS FILE BY HAND IS NOT RECOMMENDED                                 | -->
<!-- =================================================================================== -->
<robot name="meka" xmlns:controller="http://playerstage.sourceforge.net/gazebo/xmlschema/#controller" xmlns:interface="http://playerstage.sourceforge.net/gazebo/xmlschema/#interface" xmlns:sensor="http://playerstage.sourceforge.net/gazebo/xmlschema/#sensor" xmlns:xacro="http://playerstage.sourceforge.net/gazebo/xmlschema/#interface">
  <!-- Generic simulator_gazebo plugins -->
  <gazebo>
    <controller:gazebo_ros_controller_manager name="gazebo_ros_controller_manager" plugin="libgazebo_ros_controller_manager.so">
      <alwaysOn>true</alwaysOn>
      <updateRate>1000.0</updateRate>
      <interface:audio name="gazebo_ros_controller_manager_dummy_iface"/>
    </controller:gazebo_ros_controller_manager>
    <controller:gazebo_ros_power_monitor name="gazebo_ros_power_monitor_controller" plugin="libgazebo_ros_power_monitor.so">
      <alwaysOn>true</alwaysOn>
      <updateRate>1.0</updateRate>
      <timeout>5</timeout>
      <interface:audio name="power_monitor_dummy_interface"/>
      <powerStateTopic>power_state</powerStateTopic>
      <powerStateRate>10.0</powerStateRate>
      <fullChargeCapacity>87.78</fullChargeCapacity>
      <dischargeRate>-474</dischargeRate>
      <chargeRate>525</chargeRate>
      <dischargeVoltage>15.52</dischargeVoltage>
      <chargeVoltage>16.41</chargeVoltage>
    </controller:gazebo_ros_power_monitor>
  </gazebo>
  <!-- Meka Arm -->
  <!-- john added transmissions -->
  <material name="GreyA">
    <!-- darkest -->
    <color rgba="0.3 0.3 0.3 1.0"/>
  </material>
  <material name="GreyB">
    <color rgba="0.5 0.5 0.5 1.0"/>
  </material>
  <material name="GreyC">
    <color rgba="0.7 0.7 0.7 1.0"/>
  </material>
  <link name="world"/>
  <!-- Solid Base -->
  <joint name="base_joint" type="fixed">
    <origin rpy="0 0 0" xyz="0 0 1"/>
    <parent link="world"/>
    <child link="upper"/>
  </joint>
  <link name="upper">
    <inertial>
      <mass value="1000"/>
      <origin xyz="0 0 0"/>
      <inertia ixx="1000" ixy="0" ixz="0" iyy="1000" iyz="0" izz="1000"/>
    </inertial>
    <visual>
      <material name="GreyC"/>
      <origin rpy="0 0 0" xyz="0 0 0"/>
      <geometry name="upper_geom">
        <mesh filename="package://meka_description/meshes/mid_res/A2R3/A2R3_T4_Chest.dae"/>
      </geometry>
    </visual>
    <collision>
      <origin rpy="0.0 0.0 0.0 " xyz="0 0 0"/>
      <geometry name="upper_collision_geom">
        <mesh filename="package://meka_description/meshes/low_res/A2R3/A2R3_T4_Chest.stl"/>
      </geometry>
    </collision>
  </link>
  <joint name="m3joint_ma10_j0" type="revolute">
    <axis xyz="0 -1 0"/>
    <origin rpy="0 0 0" xyz="0.0 -0.18465 0.2337"/>
    <!-- transform from parent link to this joint frame -->
    <parent link="upper"/>
    <child link="shoulderupper_RIGHT"/>
    <limit effort="40" lower="-1.3962634016" upper="3.49065850399" velocity="0.523598775598"/>
    <dynamics damping="1.0"/>
  </joint>
  <link name="shoulderupper_RIGHT">
    <inertial>
      <mass value="2.0310"/>
      <origin xyz="-0.010946 0.025127 0.000022"/>
      <inertia ixx="0.003461" ixy="0.000428" ixz="0.000002" iyy="0.003097" iyz="0.000000" izz="0.005416"/>
    </inertial>
    <visual>
      <material name="GreyA"/>
      <origin rpy="0 0 0 " xyz="0 0 0"/>
      <geometry name="r_shoulder_geom">
        <mesh filename="package://meka_description/meshes/mid_res/A2R3/A2R3_RT1_shoulderRoll.dae"/>
      </geometry>
    </visual>
    <collision>
      <origin rpy="0.0 0.0 0.0 " xyz="0 0 0"/>
      <geometry name="r_shoulder_collision_geom">
        <mesh filename="package://meka_description/meshes/low_res/A2R3/A2R3_RT1_shoulderRoll.stl"/>
      </geometry>
    </collision>
  </link>
  <joint name="m3joint_ma10_j1" type="revolute">
    <axis xyz="-1 0 0"/>
    <limit effort="40" lower="-0.418879020479" upper="2.61799387799" velocity="0.523598775598"/>
    <origin rpy="0 0 0" xyz="0 0 0"/>
    <parent link="shoulderupper_RIGHT"/>
    <child link="shoulderpitch_RIGHT"/>
    <dynamics damping="1.0"/>
  </joint>
  <link name="shoulderpitch_RIGHT">
    <inertial>
      <mass value="0.566"/>
      <origin xyz="0.000944 -0.026331 -0.043257"/>
      <inertia ixx="0.000754" ixy="0.000015" ixz="0.000014" iyy="0.000921" iyz="0.000142" izz="0.000834"/>
    </inertial>
    <visual>
      <material name="GreyB"/>
      <origin rpy="0 0 0 " xyz="0 0 0"/>
      <geometry name="shoulderpitch_RIGHT">
        <mesh filename="package://meka_description/meshes/mid_res/A2R3/A2R3_RT2_shoulderPitch.dae"/>
      </geometry>
    </visual>
    <collision>
      <origin rpy="0.0 0.0 0.0 " xyz="0 0 0"/>
      <geometry name="shoulderpitch_RIGHT_collision">
        <mesh filename="package://meka_description/meshes/low_res/A2R3/A2R3_RT2_shoulderPitch.stl"/>
      </geometry>
    </collision>
  </link>
  <joint name="m3joint_ma10_j2" type="revolute">
    <axis xyz="0 0 -1"/>
    <origin rpy="0 0 0" xyz="0 -0.03175 -0.27857"/>
    <parent link="shoulderpitch_RIGHT"/>
    <child link="bicep_RIGHT"/>
    <limit effort="20" lower="-1.4835298642" upper="1.4835298642" velocity="0.872664625997"/>
    <dynamics damping="1.0"/>
  </joint>
  <link name="bicep_RIGHT">
    <inertial>
      <mass value="2.296"/>
      <origin xyz="-0.005767 0.084539 0.001385"/>
      <inertia ixx="0.013031" ixy="-0.000564" ixz="-0.000077" iyy="0.002070" iyz="0.000162" izz="0.013173"/>
    </inertial>
    <visual>
      <material name="GreyC"/>
      <origin rpy="0 0 0 " xyz="0 0 0"/>
      <geometry name="bicep_RIGHT_geom">
        <mesh filename="package://meka_description/meshes/mid_res/A2R3/A2R3_RT3_bicep.dae"/>
      </geometry>
    </visual>
    <collision>
      <origin rpy="0.0 0.0 0.0 " xyz="0 0 0"/>
      <geometry name="bicep_RIGHT_geom_collision">
        <mesh filename="package://meka_description/meshes/low_res/A2R3/A2R3_RT3_bicep.stl"/>
      </geometry>
    </collision>
  </link>
  <joint name="m3joint_ma10_j3" type="revolute">
    <axis xyz="0 -1 0"/>
    <origin rpy="0 0 0" xyz="0.00502 0  0"/>
    <parent link="bicep_RIGHT"/>
    <child link="elbowclevis_RIGHT"/>
    <limit effort="20" lower="-0.00486908464063" upper="2.31810267927" velocity="0.872664625997"/>
    <dynamics damping="10.0"/>
  </joint>
  <link name="elbowclevis_RIGHT">
    <inertial>
      <mass value="0.223"/>
      <origin xyz="-0.000002 0.000278 -0.026124"/>
      <inertia ixx="0.000470" ixy="0.000000" ixz="0.000000" iyy="0.000233" iyz="0.000019" izz="0.000425"/>
    </inertial>
    <visual>
      <material name="GreyA"/>
      <origin rpy="0 0 0 " xyz="0 0 0"/>
      <geometry name="elbowclevis_RIGHT_geom">
        <mesh filename="package://meka_description/meshes/mid_res/A2R3/A2R3_RT4_elbow.dae"/>
      </geometry>
    </visual>
    <collision>
      <origin rpy="0.0 0.0 0.0 " xyz="0 0 0"/>
      <geometry name="elbowclevis_RIGHT_collision">
        <mesh filename="package://meka_description/meshes/low_res/A2R3/A2R3_RT4_elbow.stl"/>
      </geometry>
    </collision>
  </link>
  <joint name="m3joint_ma10_j4" type="revolute">
    <axis xyz="0 0 -1"/>
    <limit effort="4" lower="-0.862192650485" upper="4.00378530407" velocity="2.61799387799"/>
    <origin rpy="0 0 0" xyz="0 0 -0.27747"/>
    <parent link="elbowclevis_RIGHT"/>
    <child link="wrist_RIGHT"/>
    <dynamics damping="1.0"/>
  </joint>
  <link name="wrist_RIGHT">
    <inertial>
      <mass value="1.468"/>
      <origin xyz="-0.004404 0.000124 0.130931"/>
      <inertia ixx="0.006099" ixy="0.000004" ixz="-0.000043" iyy="0.006120" iyz="0.000015" izz="0.001179"/>
    </inertial>
    <visual>
      <material name="GreyC"/>
      <origin rpy="0 0 0 " xyz="0 0 0"/>
      <geometry name="wrist_RIGHT_geom">
        <mesh filename="package://meka_description/meshes/mid_res/A2R3/A2R3_T5_forearmRoll.dae"/>
      </geometry>
    </visual>
    <collision>
      <origin rpy="0.0 0.0 0.0 " xyz="0 0 0"/>
      <geometry name="wrist_RIGHT_collision">
        <mesh filename="package://meka_description/meshes/low_res/A2R3/A2R3_T5_forearmRoll.stl"/>
      </geometry>
    </collision>
  </link>
  <joint name="m3joint_ma10_j5" type="revolute">
    <dynamics damping="1.0"/>
    <axis xyz="0 -1 0"/>
    <origin rpy="0 0 0" xyz="0 0 0"/>
    <parent link="wrist_RIGHT"/>
    <child link="w_differential_RIGHT"/>
    <limit effort="8" lower="-1.02677719895" upper="1.02677719895" velocity="0.698131700798"/>
    <dynamics damping="1.0"/>
  </joint>
  <link name="w_differential_RIGHT">
    <inertial>
      <mass value="0.278"/>
      <origin xyz="0 0 0"/>
      <inertia ixx="0" ixy="0" ixz="0" iyy="0" iyz="0" izz="0"/>
    </inertial>
    <visual>
      <material name="GreyB"/>
      <origin rpy="0 0 0 " xyz="0 0 0"/>
      <geometry name="w_differential_RIGHT_geom">
        <mesh filename="package://meka_description/meshes/mid_res/A2R3/A2R3_T6_wristDiff.dae"/>
      </geometry>
    </visual>
    <collision>
      <origin rpy="0.0 0.0 0.0 " xyz="0 0 0"/>
      <geometry name="w_differential_RIGHT_collision">
        <box size="0.01 0.01 0.01"/>
      </geometry>
    </collision>
  </link>
  <joint name="m3joint_ma10_j6" type="revolute">
    <axis xyz="-1 0 0"/>
    <limit effort="8" lower="-1.0471975512" upper="1.0471975512" velocity="0.698131700798"/>
    <origin rpy="0 0 0" xyz="0 0 0"/>
    <parent link="w_differential_RIGHT"/>
    <child link="handmount_RIGHT"/>
    <dynamics damping="1.0"/>
  </joint>
  <link name="handmount_RIGHT">
    <inertial>
      <mass value="0.093"/>
      <origin xyz="0 0 0"/>
      <inertia ixx="0" ixy="0" ixz="0" iyy="0" iyz="0" izz="0"/>
    </inertial>
    <visual>
      <material name="GreyA"/>
      <origin rpy="0 0 0 " xyz="0 0 0"/>
      <geometry name="handmount_RIGHT_geom">
        <mesh filename="package://meka_description/meshes/mid_res/A2R3/A2R3_T7_wristYaw.dae"/>
      </geometry>
    </visual>
    <collision>
      <origin rpy="0.0 0.0 0.0 " xyz="0 0 0"/>
      <geometry name="handmount_RIGHT_collision">
        <mesh filename="package://meka_description/meshes/low_res/A2R3/A2R3_T7_wristYaw.stl"/>
      </geometry>
    </collision>
  </link>
  <!-- john added transmissions -->
  <transmission name="m3joint_ma10_t0" type="pr2_mechanism_model/SimpleTransmission">
    <actuator name="m3joint_ma10_a0"/>
    <joint name="m3joint_ma10_j0"/>
    <mechanicalReduction>1</mechanicalReduction>
  </transmission>
  <transmission name="m3joint_ma10_t1" type="pr2_mechanism_model/SimpleTransmission">
    <actuator name="m3joint_ma10_a1"/>
    <joint name="m3joint_ma10_j1"/>
    <mechanicalReduction>1</mechanicalReduction>
  </transmission>
  <transmission name="m3joint_ma10_t2" type="pr2_mechanism_model/SimpleTransmission">
    <actuator name="m3joint_ma10_a2"/>
    <joint name="m3joint_ma10_j2"/>
    <mechanicalReduction>1</mechanicalReduction>
  </transmission>
  <transmission name="m3joint_ma10_t3" type="pr2_mechanism_model/SimpleTransmission">
    <actuator name="m3joint_ma10_a3"/>
    <joint name="m3joint_ma10_j3"/>
    <mechanicalReduction>1</mechanicalReduction>
  </transmission>
  <transmission name="m3joint_ma10_t4" type="pr2_mechanism_model/SimpleTransmission">
    <actuator name="m3joint_ma10_a4"/>
    <joint name="m3joint_ma10_j4"/>
    <mechanicalReduction>1</mechanicalReduction>
  </transmission>
  <transmission name="m3joint_ma10_t5" type="pr2_mechanism_model/SimpleTransmission">
    <actuator name="m3joint_ma10_a5"/>
    <joint name="m3joint_ma10_j5"/>
    <mechanicalReduction>1</mechanicalReduction>
  </transmission>
  <transmission name="m3joint_ma10_t6" type="pr2_mechanism_model/SimpleTransmission">
    <actuator name="m3joint_ma10_a6"/>
    <joint name="m3joint_ma10_j6"/>
    <mechanicalReduction>1</mechanicalReduction>
  </transmission>
</robot>
