<?xml version="1.0"?>
<robot xmlns:sensor="http://playerstage.sourceforge.net/gazebo/xmlschema/#sensor"
       xmlns:controller="http://playerstage.sourceforge.net/gazebo/xmlschema/#controller"
       xmlns:interface="http://playerstage.sourceforge.net/gazebo/xmlschema/#interface">

  <property name="M_PI" value="3.1415926535897931" />
 

  <macro name="m3_r_shoulder" params="side parent reflect *origin">

    <!-- Shoulder pan -->
    <joint name="m3joint_${R_ARM}_j0" type="revolute">
      <axis xyz="0 -1 0" />
      <insert_block name="origin" /> <!-- transform from parent link to this joint frame -->
      <parent link="${parent}"/>
      <child link="shoulderupper_RIGHT"/>
      <limit effort="40" velocity="${30.0*M_PI/180}" lower="${-80*M_PI/180}" upper="${200*M_PI/180}" />
      <dynamics damping="1.0"/>
    </joint>
    <link name="shoulderupper_RIGHT">
      <inertial>
        <mass value="2.0310" />
	<origin xyz="-0.010946 0.025127 0.000022"/>                
	<inertia ixx="0.003461"
	iyy="0.003097"
	izz="0.005416"
	ixy="0.000428"
	ixz="0.000002"
	iyz="0.000000" />
      </inertial>

      <visual>
	      <material name="GreyA" />
	      <origin xyz="0 0 0" rpy="0 0 0 " />
	      <geometry name="r_shoulder_geom">
		      <mesh filename="package://${MESH}/A2R3/A2R3_RT1_shoulderRoll.dae" />
	      </geometry>  
      </visual>

      <collision>
	      <origin xyz="0 0 0" rpy="0.0 0.0 0.0 " />
	      <geometry name="r_shoulder_collision_geom">
		      <mesh filename="package://${MESH_COLL}/A2R3/A2R3_RT1_shoulderRoll.stl" />
	      </geometry>
      </collision>
    </link>

    
    <joint name="m3joint_${R_ARM}_j1" type="revolute">
      <axis xyz="-1 0 0"/>
     <limit effort="40" velocity="${30*M_PI/180}" lower="${-24*M_PI/180}" upper="${150*M_PI/180}" />    
      <origin xyz="0 0 0" rpy="0 0 0" />
      <parent link="shoulderupper_RIGHT"/>
      <child link="shoulderpitch_RIGHT"/>
      <dynamics damping="1.0"/>
    </joint>
    <link name="shoulderpitch_RIGHT">

      <inertial>
        <mass value="0.566" />
        <origin xyz="0.000944 -0.026331 -0.043257"/>
	<inertia ixx="0.000754"
	iyy="0.000921"
	izz="0.000834"
	ixy="0.000015"
	ixz="0.000014"
	iyz="0.000142" />
      </inertial>

      <visual>
	      <material name="GreyB" />
	      <origin xyz="0 0 0" rpy="0 0 0 " />
	      <geometry name="shoulderpitch_RIGHT">
		      <mesh filename="package://${MESH}/A2R3/A2R3_RT2_shoulderPitch.dae" />		      
	      </geometry>  
      </visual>
      
      <collision>
	      <origin xyz="0 0 0" rpy="0.0 0.0 0.0 " />
	      <geometry name="shoulderpitch_RIGHT_collision">
		      <mesh filename="package://${MESH_COLL}/A2R3/A2R3_RT2_shoulderPitch.stl" />
	      </geometry>
      </collision>
    </link>

  

    <joint name="m3joint_${R_ARM}_j2" type="revolute">
      <axis xyz="0 0 -1" />
      <origin xyz="0 -0.03175 -0.27857" rpy="0 0 0" />
      <parent link="shoulderpitch_RIGHT" />
      <child link="bicep_RIGHT"/>
      <limit effort="20" velocity="${50*M_PI/180}" lower="${-85*M_PI/180}" upper="${85*M_PI/180}" />    
      <dynamics damping="1.0"/>
    </joint>
    <link name="bicep_RIGHT">
      <inertial>        
        <mass value="2.296" />
        <origin xyz="-0.005767 0.084539 0.001385"/>
	<inertia ixx="0.013031"
	iyy="0.002070"
	izz="0.013173"
	ixy="-0.000564"
	ixz="-0.000077"
	iyz="0.000162" />
      </inertial>        
      <visual>
	      <material name="GreyC" />
	      <origin xyz="0 0 0" rpy="0 0 0 " />
	      <geometry name="bicep_RIGHT_geom">
		      <mesh filename="package://${MESH}/A2R3/A2R3_RT3_bicep.dae" />
	      </geometry>  
      </visual>
      
      <collision>
	      <origin xyz="0 0 0" rpy="0.0 0.0 0.0 " />
	      <geometry name="bicep_RIGHT_geom_collision">
		      <mesh filename="package://${MESH_COLL}/A2R3/A2R3_RT3_bicep.stl" />
	      </geometry>
      </collision>
    </link>

  </macro>



  <!-- ============================   Upper Arm   ============================ -->


  <macro name="m3_r_upper_arm" params="side parent reflect">

	  <joint name="m3joint_${R_ARM}_j3" type="revolute">
		  <axis xyz="0 -1 0" />
		  <origin xyz="0.00502 0  0" rpy="0 0 0" />
      <parent link="${parent}"/>
      <child link="elbowclevis_RIGHT"/>
	<limit effort="20" velocity="${50*M_PI/180}" lower="${-0.278978*M_PI/180}" upper="${132.8175*M_PI/180}" />    
      <dynamics damping="10.0" />
    </joint>
    <link name="elbowclevis_RIGHT">

      <inertial>       
        <mass value="0.223" />
        <origin xyz="-0.000002 0.000278 -0.026124"/>
	<inertia ixx="0.000470"
	iyy="0.000233"
	izz="0.000425"
	ixy="0.000000"
	ixz="0.000000"
	iyz="0.000019" />
      </inertial>

      <visual>
	      <material name="GreyA" />
	      <origin xyz="0 0 0" rpy="0 0 0 " />
	      <geometry name="elbowclevis_RIGHT_geom">
		      <mesh filename="package://${MESH}/A2R3/A2R3_RT4_elbow.dae" />
	      </geometry>  
      </visual>
      
      <collision>
	      <origin xyz="0 0 0" rpy="0.0 0.0 0.0 " />
	      <geometry name="elbowclevis_RIGHT_collision">
		      <mesh filename="package://${MESH_COLL}/A2R3/A2R3_RT4_elbow.stl" />
	      </geometry>
      </collision>

    </link>

  

    <joint name="m3joint_${R_ARM}_j4" type="revolute">
	    <axis xyz="0 0 -1" />
      <limit effort="4" velocity="${150*M_PI/180}" lower="${-49.4*M_PI/180}" upper="${229.4*M_PI/180}" /> 
      <origin xyz="0 0 -0.27747" rpy="0 0 0" />
      <parent link="elbowclevis_RIGHT"/>
      <child link="wrist_RIGHT"/>
      <dynamics damping="1.0"/>
    </joint>
    <link name="wrist_RIGHT">

      <inertial>
        <mass value="1.468" />
        <origin xyz="-0.004404 0.000124 0.130931"/>
	<inertia ixx="0.006099"
	iyy="0.006120"
	izz="0.001179"
	ixy="0.000004"
	ixz="-0.000043"
	iyz="0.000015" />
      </inertial>

      <visual>
	      <material name="GreyC" />
	      <origin xyz="0 0 0" rpy="0 0 0 " />
	      <geometry name="wrist_RIGHT_geom">
		      <mesh filename="package://${MESH}/A2R3/A2R3_T5_forearmRoll.dae" />
	      </geometry>  
      </visual>
      
      <collision>
	      <origin xyz="0 0 0" rpy="0.0 0.0 0.0 " />
	      <geometry name="wrist_RIGHT_collision">
		      <mesh filename="package://${MESH_COLL}/A2R3/A2R3_T5_forearmRoll.stl" />
	      </geometry>
      </collision>
    </link>
       

  </macro>


  <!-- ============================   Forearm   ============================ -->

  <macro name="m3_r_forearm" params="side parent reflect">

	  <joint name="m3joint_${R_ARM}_j5" type="revolute">
      <dynamics damping="1.0" />
		  <axis xyz="0 -1 0" />
      <origin xyz="0 0 0" rpy="0 0 0" />
      <parent link="${parent}"/>
      <child link="w_differential_RIGHT"/>
	<limit effort="8" velocity="${40*M_PI/180}" lower="${-58.83*M_PI/180}" upper="${58.83*M_PI/180}" /> 
      <dynamics damping="1.0"/>
    </joint>
    <link name="w_differential_RIGHT">

      <inertial>
        <mass value="0.278" />
        <origin xyz="0 0 0" />
        <inertia ixx="0" ixy="0" ixz="0"
                 iyy="0" iyz="0"
                 izz="0" />
      </inertial>

      <visual>
	      <material name="GreyB" />
	      <origin xyz="0 0 0" rpy="0 0 0 " />
	      <geometry name="w_differential_RIGHT_geom">
		      <mesh filename="package://${MESH}/A2R3/A2R3_T6_wristDiff.dae" />
	      </geometry>  
      </visual>
      
      <collision>
	      <origin xyz="0 0 0" rpy="0.0 0.0 0.0 " />
	      <geometry name="w_differential_RIGHT_collision">
		      <box size="0.01 0.01 0.01" />
	      </geometry>
      </collision>
    </link>

    

    <joint name="m3joint_${R_ARM}_j6" type="revolute">
	    <axis xyz="-1 0 0" />
      <limit effort="8" velocity="${40*M_PI/180}" lower="${-60*M_PI/180}" upper="${60*M_PI/180}" /> 
      <origin xyz="0 0 0" rpy="0 0 0" />
      <parent link="w_differential_RIGHT"/>
      <child link="handmount_RIGHT"/>
      <dynamics damping="1.0"/>
    </joint>
    <link name="handmount_RIGHT">

      <inertial>
        <mass value="0.093" />
        <origin xyz="0 0 0" />
        <inertia ixx="0" ixy="0" ixz="0"
                 iyy="0" iyz="0"
                 izz="0" />
      </inertial>

      <visual>
	      <material name="GreyA" />
	      <origin xyz="0 0 0" rpy="0 0 0 " />
	      <geometry name="handmount_RIGHT_geom">
		       <mesh filename="package://${MESH}/A2R3/A2R3_T7_wristYaw.dae" />
	      </geometry>  
      </visual>
      
      <collision>
	      <origin xyz="0 0 0" rpy="0.0 0.0 0.0 " />
	      <geometry name="handmount_RIGHT_collision">
		      <mesh filename="package://${MESH_COLL}/A2R3/A2R3_T7_wristYaw.stl" />
	      </geometry>
      </collision>
    </link>

  </macro>



  <macro name="m3_r_arm" params="side parent reflect *origin">
    <m3_r_shoulder side="${side}" reflect="${reflect}" parent="${parent}">
      <insert_block name="origin" />
    </m3_r_shoulder>
    <m3_r_upper_arm side="${side}" reflect="${reflect}" parent="bicep_RIGHT" />
    <m3_r_forearm side="${side}" reflect="${reflect}" parent="wrist_RIGHT" />
  </macro>


</robot>
