<?xml version="1.0" ?>
<!-- =================================================================================== -->
<!-- |    This document was autogenerated by xacro from uta.urdf.xacro                 | -->
<!-- |    EDITING THIS FILE BY HAND IS NOT RECOMMENDED                                 | -->
<!-- =================================================================================== -->
<robot name="uta" xmlns:controller="http://playerstage.sourceforge.net/gazebo/xmlschema/#controller" xmlns:interface="http://playerstage.sourceforge.net/gazebo/xmlschema/#interface" xmlns:sensor="http://playerstage.sourceforge.net/gazebo/xmlschema/#sensor" xmlns:xacro="http://playerstage.sourceforge.net/gazebo/xmlschema/#interface">
  <!-- generic simulator_gazebo plugins for starting mechanism control, ros time, ros battery -->
  <gazebo>
    <controller:gazebo_ros_controller_manager name="gazebo_ros_controller_manager" plugin="libgazebo_ros_controller_manager.so">
      <alwaysOn>true</alwaysOn>
      <updateRate>10000.0</updateRate>
    </controller:gazebo_ros_controller_manager>
  </gazebo>
  <transmission name="m3joint_mt3_t0" type="pr2_mechanism_model/SimpleTransmission">
    <actuator name="m3joint_mt3_a0"/>
    <joint name="m3joint_mt3_j0"/>
    <mechanicalReduction>1</mechanicalReduction>
  </transmission>
  <transmission name="m3joint_mt3_t1" type="pr2_mechanism_model/SimpleTransmission">
    <actuator name="m3joint_mt3_a1"/>
    <joint name="m3joint_mt3_j1"/>
    <mechanicalReduction>1</mechanicalReduction>
  </transmission>
  <transmission name="m3joint_slave_mt3_t2" type="pr2_mechanism_model/SimpleTransmission">
    <actuator name="m3joint_slave_mt3_a2"/>
    <joint name="m3joint_slave_mt3_j2"/>
    <mechanicalReduction>1</mechanicalReduction>
  </transmission>
  <!-- Meka Arm -->
  <!-- Meka Hand -->
  <!-- Meka Head -->
  <!-- john added transmissions -->
  <material name="GreyA">
    <!-- darkest -->
    <color rgba="0.3 0.3 0.3 1.0"/>
  </material>
  <material name="GreyB">
    <color rgba="0.5 0.5 0.5 1.0"/>
  </material>
  <material name="GreyC">
    <color rgba="0.7 0.7 0.7 1.0"/>
  </material>
  <joint name="m3joint_ma10_j0" type="revolute">
    <axis xyz="0 -1 0"/>
    <origin rpy="0 0 0" xyz="0.0 -0.18465 0.2337"/>
    <!-- transform from parent link to this joint frame -->
    <parent link="upper"/>
    <child link="shoulderupper_RIGHT"/>
    <limit effort="40" lower="-1.3962634016" upper="3.49065850399" velocity="0.523598775598"/>
    <dynamics damping="1.0"/>
  </joint>
  <link name="shoulderupper_RIGHT">
    <inertial>
      <mass value="2.0310"/>
      <origin xyz="-0.010946 0.025127 0.000022"/>
      <inertia ixx="0.003461" ixy="0.000428" ixz="0.000002" iyy="0.003097" iyz="0.000000" izz="0.005416"/>
    </inertial>
    <visual>
      <material name="GreyA"/>
      <origin rpy="0 0 0 " xyz="0 0 0"/>
      <geometry name="r_shoulder_geom">
        <mesh filename="package://meka_description/meshes/mid_res/A2R3/A2R3_RT1_shoulderRoll.dae"/>
      </geometry>
    </visual>
    <collision>
      <origin rpy="0.0 0.0 0.0 " xyz="0 0 0"/>
      <geometry name="r_shoulder_collision_geom">
        <mesh filename="package://meka_description/meshes/low_res/A2R3/A2R3_RT1_shoulderRoll.stl"/>
      </geometry>
    </collision>
  </link>
  <joint name="m3joint_ma10_j1" type="revolute">
    <axis xyz="-1 0 0"/>
    <limit effort="40" lower="-0.418879020479" upper="2.61799387799" velocity="0.523598775598"/>
    <origin rpy="0 0 0" xyz="0 0 0"/>
    <parent link="shoulderupper_RIGHT"/>
    <child link="shoulderpitch_RIGHT"/>
    <dynamics damping="1.0"/>
  </joint>
  <link name="shoulderpitch_RIGHT">
    <inertial>
      <mass value="0.566"/>
      <origin xyz="0.000944 -0.026331 -0.043257"/>
      <inertia ixx="0.000754" ixy="0.000015" ixz="0.000014" iyy="0.000921" iyz="0.000142" izz="0.000834"/>
    </inertial>
    <visual>
      <material name="GreyB"/>
      <origin rpy="0 0 0 " xyz="0 0 0"/>
      <geometry name="shoulderpitch_RIGHT">
        <mesh filename="package://meka_description/meshes/mid_res/A2R3/A2R3_RT2_shoulderPitch.dae"/>
      </geometry>
    </visual>
    <collision>
      <origin rpy="0.0 0.0 0.0 " xyz="0 0 0"/>
      <geometry name="shoulderpitch_RIGHT_collision">
        <mesh filename="package://meka_description/meshes/low_res/A2R3/A2R3_RT2_shoulderPitch.stl"/>
      </geometry>
    </collision>
  </link>
  <joint name="m3joint_ma10_j2" type="revolute">
    <axis xyz="0 0 -1"/>
    <origin rpy="0 0 0" xyz="0 -0.03175 -0.27857"/>
    <parent link="shoulderpitch_RIGHT"/>
    <child link="bicep_RIGHT"/>
    <limit effort="20" lower="-1.4835298642" upper="1.4835298642" velocity="0.872664625997"/>
    <dynamics damping="1.0"/>
  </joint>
  <link name="bicep_RIGHT">
    <inertial>
      <mass value="2.296"/>
      <origin xyz="-0.005767 0.084539 0.001385"/>
      <inertia ixx="0.013031" ixy="-0.000564" ixz="-0.000077" iyy="0.002070" iyz="0.000162" izz="0.013173"/>
    </inertial>
    <visual>
      <material name="GreyC"/>
      <origin rpy="0 0 0 " xyz="0 0 0"/>
      <geometry name="bicep_RIGHT_geom">
        <mesh filename="package://meka_description/meshes/mid_res/A2R3/A2R3_RT3_bicep.dae"/>
      </geometry>
    </visual>
    <collision>
      <origin rpy="0.0 0.0 0.0 " xyz="0 0 0"/>
      <geometry name="bicep_RIGHT_geom_collision">
        <mesh filename="package://meka_description/meshes/low_res/A2R3/A2R3_RT3_bicep.stl"/>
      </geometry>
    </collision>
  </link>
  <joint name="m3joint_ma10_j3" type="revolute">
    <axis xyz="0 -1 0"/>
    <origin rpy="0 0 0" xyz="0.00502 0  0"/>
    <parent link="bicep_RIGHT"/>
    <child link="elbowclevis_RIGHT"/>
    <limit effort="20" lower="-0.00486908464063" upper="2.31810267927" velocity="0.872664625997"/>
    <dynamics damping="10.0"/>
  </joint>
  <link name="elbowclevis_RIGHT">
    <inertial>
      <mass value="0.223"/>
      <origin xyz="-0.000002 0.000278 -0.026124"/>
      <inertia ixx="0.000470" ixy="0.000000" ixz="0.000000" iyy="0.000233" iyz="0.000019" izz="0.000425"/>
    </inertial>
    <visual>
      <material name="GreyA"/>
      <origin rpy="0 0 0 " xyz="0 0 0"/>
      <geometry name="elbowclevis_RIGHT_geom">
        <mesh filename="package://meka_description/meshes/mid_res/A2R3/A2R3_RT4_elbow.dae"/>
      </geometry>
    </visual>
    <collision>
      <origin rpy="0.0 0.0 0.0 " xyz="0 0 0"/>
      <geometry name="elbowclevis_RIGHT_collision">
        <mesh filename="package://meka_description/meshes/low_res/A2R3/A2R3_RT4_elbow.stl"/>
      </geometry>
    </collision>
  </link>
  <joint name="m3joint_ma10_j4" type="revolute">
    <axis xyz="0 0 -1"/>
    <limit effort="4" lower="-0.862192650485" upper="4.00378530407" velocity="2.61799387799"/>
    <origin rpy="0 0 0" xyz="0 0 -0.27747"/>
    <parent link="elbowclevis_RIGHT"/>
    <child link="wrist_RIGHT"/>
    <dynamics damping="1.0"/>
  </joint>
  <link name="wrist_RIGHT">
    <inertial>
      <mass value="1.468"/>
      <origin xyz="-0.004404 0.000124 0.130931"/>
      <inertia ixx="0.006099" ixy="0.000004" ixz="-0.000043" iyy="0.006120" iyz="0.000015" izz="0.001179"/>
    </inertial>
    <visual>
      <material name="GreyC"/>
      <origin rpy="0 0 0 " xyz="0 0 0"/>
      <geometry name="wrist_RIGHT_geom">
        <mesh filename="package://meka_description/meshes/mid_res/A2R3/A2R3_T5_forearmRoll.dae"/>
      </geometry>
    </visual>
    <collision>
      <origin rpy="0.0 0.0 0.0 " xyz="0 0 0"/>
      <geometry name="wrist_RIGHT_collision">
        <mesh filename="package://meka_description/meshes/low_res/A2R3/A2R3_T5_forearmRoll.stl"/>
      </geometry>
    </collision>
  </link>
  <joint name="m3joint_ma10_j5" type="revolute">
    <dynamics damping="1.0"/>
    <axis xyz="0 -1 0"/>
    <origin rpy="0 0 0" xyz="0 0 0"/>
    <parent link="wrist_RIGHT"/>
    <child link="w_differential_RIGHT"/>
    <limit effort="8" lower="-1.02677719895" upper="1.02677719895" velocity="0.698131700798"/>
    <dynamics damping="1.0"/>
  </joint>
  <link name="w_differential_RIGHT">
    <inertial>
      <mass value="0.278"/>
      <origin xyz="0 0 0"/>
      <inertia ixx="0" ixy="0" ixz="0" iyy="0" iyz="0" izz="0"/>
    </inertial>
    <visual>
      <material name="GreyB"/>
      <origin rpy="0 0 0 " xyz="0 0 0"/>
      <geometry name="w_differential_RIGHT_geom">
        <mesh filename="package://meka_description/meshes/mid_res/A2R3/A2R3_T6_wristDiff.dae"/>
      </geometry>
    </visual>
    <collision>
      <origin rpy="0.0 0.0 0.0 " xyz="0 0 0"/>
      <geometry name="w_differential_RIGHT_collision">
        <box size="0.01 0.01 0.01"/>
      </geometry>
    </collision>
  </link>
  <joint name="m3joint_ma10_j6" type="revolute">
    <axis xyz="-1 0 0"/>
    <limit effort="8" lower="-1.0471975512" upper="1.0471975512" velocity="0.698131700798"/>
    <origin rpy="0 0 0" xyz="0 0 0"/>
    <parent link="w_differential_RIGHT"/>
    <child link="handmount_RIGHT"/>
    <dynamics damping="1.0"/>
  </joint>
  <link name="handmount_RIGHT">
    <inertial>
      <mass value="0.093"/>
      <origin xyz="0 0 0"/>
      <inertia ixx="0" ixy="0" ixz="0" iyy="0" iyz="0" izz="0"/>
    </inertial>
    <visual>
      <material name="GreyA"/>
      <origin rpy="0 0 0 " xyz="0 0 0"/>
      <geometry name="handmount_RIGHT_geom">
        <mesh filename="package://meka_description/meshes/mid_res/A2R3/A2R3_T7_wristYaw.dae"/>
      </geometry>
    </visual>
    <collision>
      <origin rpy="0.0 0.0 0.0 " xyz="0 0 0"/>
      <geometry name="handmount_RIGHT_collision">
        <mesh filename="package://meka_description/meshes/low_res/A2R3/A2R3_T7_wristYaw.stl"/>
      </geometry>
    </collision>
  </link>
  <!-- john added transmissions -->
  <transmission name="m3joint_ma10_t0" type="pr2_mechanism_model/SimpleTransmission">
    <actuator name="m3joint_ma10_a0"/>
    <joint name="m3joint_ma10_j0"/>
    <mechanicalReduction>1</mechanicalReduction>
  </transmission>
  <transmission name="m3joint_ma10_t1" type="pr2_mechanism_model/SimpleTransmission">
    <actuator name="m3joint_ma10_a1"/>
    <joint name="m3joint_ma10_j1"/>
    <mechanicalReduction>1</mechanicalReduction>
  </transmission>
  <transmission name="m3joint_ma10_t2" type="pr2_mechanism_model/SimpleTransmission">
    <actuator name="m3joint_ma10_a2"/>
    <joint name="m3joint_ma10_j2"/>
    <mechanicalReduction>1</mechanicalReduction>
  </transmission>
  <transmission name="m3joint_ma10_t3" type="pr2_mechanism_model/SimpleTransmission">
    <actuator name="m3joint_ma10_a3"/>
    <joint name="m3joint_ma10_j3"/>
    <mechanicalReduction>1</mechanicalReduction>
  </transmission>
  <transmission name="m3joint_ma10_t4" type="pr2_mechanism_model/SimpleTransmission">
    <actuator name="m3joint_ma10_a4"/>
    <joint name="m3joint_ma10_j4"/>
    <mechanicalReduction>1</mechanicalReduction>
  </transmission>
  <transmission name="m3joint_ma10_t5" type="pr2_mechanism_model/SimpleTransmission">
    <actuator name="m3joint_ma10_a5"/>
    <joint name="m3joint_ma10_j5"/>
    <mechanicalReduction>1</mechanicalReduction>
  </transmission>
  <transmission name="m3joint_ma10_t6" type="pr2_mechanism_model/SimpleTransmission">
    <actuator name="m3joint_ma10_a6"/>
    <joint name="m3joint_ma10_j6"/>
    <mechanicalReduction>1</mechanicalReduction>
  </transmission>
  <transmission name="m3joint_ua_mh8_t0" type="pr2_mechanism_model/SimpleTransmission">
    <actuator name="m3joint_ua_mh8_a0"/>
    <joint name="m3joint_ua_mh8_j0"/>
    <mechanicalReduction>1</mechanicalReduction>
  </transmission>
  <transmission name="m3joint_ua_mh8_t1" type="pr2_mechanism_model/SimpleTransmission">
    <actuator name="m3joint_ua_mh8_a1"/>
    <joint name="m3joint_ua_mh8_j1"/>
    <mechanicalReduction>1</mechanicalReduction>
  </transmission>
  <transmission name="m3joint_ua_mh8_t2" type="pr2_mechanism_model/SimpleTransmission">
    <actuator name="m3joint_ua_mh8_a2"/>
    <joint name="m3joint_ua_mh8_j2"/>
    <mechanicalReduction>1</mechanicalReduction>
  </transmission>
  <transmission name="m3joint_ua_mh8_t3" type="pr2_mechanism_model/SimpleTransmission">
    <actuator name="m3joint_ua_mh8_a3"/>
    <joint name="m3joint_ua_mh8_j3"/>
    <mechanicalReduction>1</mechanicalReduction>
  </transmission>
  <transmission name="m3joint_ua_mh8_t4" type="pr2_mechanism_model/SimpleTransmission">
    <actuator name="m3joint_ua_mh8_a4"/>
    <joint name="m3joint_ua_mh8_j4"/>
    <mechanicalReduction>1</mechanicalReduction>
  </transmission>
  <transmission name="m3joint_ua_mh8_t5" type="pr2_mechanism_model/SimpleTransmission">
    <actuator name="m3joint_ua_mh8_a5"/>
    <joint name="m3joint_ua_mh8_j5"/>
    <mechanicalReduction>1</mechanicalReduction>
  </transmission>
  <transmission name="m3joint_ua_mh8_t6" type="pr2_mechanism_model/SimpleTransmission">
    <actuator name="m3joint_ua_mh8_a6"/>
    <joint name="m3joint_ua_mh8_j6"/>
    <mechanicalReduction>1</mechanicalReduction>
  </transmission>
  <transmission name="m3joint_ua_mh8_t7" type="pr2_mechanism_model/SimpleTransmission">
    <actuator name="m3joint_ua_mh8_a7"/>
    <joint name="m3joint_ua_mh8_j7"/>
    <mechanicalReduction>1</mechanicalReduction>
  </transmission>
  <transmission name="m3joint_ua_mh8_t8" type="pr2_mechanism_model/SimpleTransmission">
    <actuator name="m3joint_ua_mh8_a8"/>
    <joint name="m3joint_ua_mh8_j8"/>
    <mechanicalReduction>1</mechanicalReduction>
  </transmission>
  <transmission name="m3joint_ua_mh8_t9" type="pr2_mechanism_model/SimpleTransmission">
    <actuator name="m3joint_ua_mh8_a9"/>
    <joint name="m3joint_ua_mh8_j9"/>
    <mechanicalReduction>1</mechanicalReduction>
  </transmission>
  <transmission name="m3joint_ua_mh8_t10" type="pr2_mechanism_model/SimpleTransmission">
    <actuator name="m3joint_ua_mh8_a10"/>
    <joint name="m3joint_ua_mh8_j10"/>
    <mechanicalReduction>1</mechanicalReduction>
  </transmission>
  <transmission name="m3joint_ua_mh8_t11" type="pr2_mechanism_model/SimpleTransmission">
    <actuator name="m3joint_ua_mh8_a11"/>
    <joint name="m3joint_ua_mh8_j11"/>
    <mechanicalReduction>1</mechanicalReduction>
  </transmission>
  <transmission name="m3joint_ms2_t0" type="pr2_mechanism_model/SimpleTransmission">
    <actuator name="m3joint_ms2_a0"/>
    <joint name="m3joint_ms2_j0"/>
    <mechanicalReduction>1</mechanicalReduction>
  </transmission>
  <transmission name="m3joint_ms2_t1" type="pr2_mechanism_model/SimpleTransmission">
    <actuator name="m3joint_ms2_a1"/>
    <joint name="m3joint_ms2_j1"/>
    <mechanicalReduction>1</mechanicalReduction>
  </transmission>
  <transmission name="m3joint_ms2_t2" type="pr2_mechanism_model/SimpleTransmission">
    <actuator name="m3joint_ms2_a2"/>
    <joint name="m3joint_ms2_j2"/>
    <mechanicalReduction>1</mechanicalReduction>
  </transmission>
  <transmission name="m3joint_ms2_t3" type="pr2_mechanism_model/SimpleTransmission">
    <actuator name="m3joint_ms2_a3"/>
    <joint name="m3joint_ms2_j3"/>
    <mechanicalReduction>1</mechanicalReduction>
  </transmission>
  <transmission name="m3joint_ms2_t4" type="pr2_mechanism_model/SimpleTransmission">
    <actuator name="m3joint_ms2_a4"/>
    <joint name="m3joint_ms2_j4"/>
    <mechanicalReduction>1</mechanicalReduction>
  </transmission>
  <transmission name="m3joint_ms2_t5" type="pr2_mechanism_model/SimpleTransmission">
    <actuator name="m3joint_ms2_a5"/>
    <joint name="m3joint_ms2_j5"/>
    <mechanicalReduction>1</mechanicalReduction>
  </transmission>
  <transmission name="m3joint_ms2_t6" type="pr2_mechanism_model/SimpleTransmission">
    <actuator name="m3joint_ms2_a6"/>
    <joint name="m3joint_ms2_j6"/>
    <mechanicalReduction>1</mechanicalReduction>
  </transmission>
  <joint name="m3joint_ms2_j0" type="revolute">
    <axis xyz="0 -1 0"/>
    <origin rpy="0 0 0" xyz="0.0 0.0 0.31155"/>
    <!-- transform from parent link to this joint frame -->
    <parent link="upper"/>
    <child link="neck_tilt"/>
    <limit effort="100" lower="-0.698131700798" upper="0.261799387799" velocity="0.349065850399"/>
  </joint>
  <link name="neck_tilt">
    <inertial>
      <mass value="0.940"/>
      <origin xyz="0.000061 0.003310 0.028798"/>
      <inertia ixx="0.001395" ixy="-0.000000" ixz="-0.000000" iyy="0.001345" iyz="-0.000085" izz="0.000392"/>
    </inertial>
    <visual>
      <material name="GreyA"/>
      <origin rpy="0 0 0 " xyz="0 0 0"/>
      <geometry name="neck_tilt_geom">
        <mesh filename="package://meka_description/meshes/mid_res/S2R1/S2R1_SH1_neckTilt.dae"/>
      </geometry>
    </visual>
    <collision>
      <origin rpy="0.0 0.0 0.0 " xyz="0 0 0"/>
      <geometry name="neck_tilt_geom_collison">
        <mesh filename="package://meka_description/meshes/low_res/S2R1/S2R1_SH1_neckTilt.stl"/>
      </geometry>
    </collision>
  </link>
  <joint name="m3joint_ms2_j1" type="revolute">
    <axis xyz="0 0 1"/>
    <limit effort="100" lower="-1.41230297742" upper="1.41214589779" velocity="1.308996939"/>
    <origin rpy="0 0 0" xyz="0 0 0.13849"/>
    <parent link="neck_tilt"/>
    <child link="neck_roll"/>
  </joint>
  <link name="neck_roll">
    <inertial>
      <mass value="0.409"/>
      <origin xyz="0.0 0.0 0.0"/>
      <inertia ixx="0.0" ixy="0.0" ixz="0.0" iyy="0.0" iyz="0.0" izz="0.0"/>
    </inertial>
    <visual>
      <material name="GreyB"/>
      <origin rpy="0 0 0 " xyz="0 0 0"/>
      <geometry name="neck_roll_geom">
        <mesh filename="package://meka_description/meshes/mid_res/S2R1/S2R1_SH2_neckRoll.dae"/>
      </geometry>
    </visual>
    <collision>
      <origin rpy="0.0 0.0 0.0 " xyz="0 0 0"/>
      <geometry name="S2R1_SH2_neckRoll_collision">
        <box size="0.01 0.01 0.01"/>
      </geometry>
    </collision>
  </link>
  <joint name="m3joint_ms2_j2" type="revolute">
    <axis xyz="-1 0 0"/>
    <origin rpy="0 0 0" xyz="0 0 0"/>
    <parent link="neck_roll"/>
    <child link="neck_yaw"/>
    <limit effort="100" lower="-0.260752190248" upper="0.260752190248" velocity="0.872664625997"/>
  </joint>
  <link name="neck_yaw">
    <inertial>
      <mass value="0.496"/>
      <origin xyz="-0.010690 0.053982 0.000045"/>
      <inertia ixx="0.001094" ixy="0.000284" ixz="0.000000" iyy="0.000311" iyz="0.000000" izz="0.001222"/>
    </inertial>
    <visual>
      <material name="GreyC"/>
      <origin rpy="0 0 0 " xyz="0 0 0"/>
      <geometry name="S2R1_H3_neckYaw_geom">
        <mesh filename="package://meka_description/meshes/mid_res/S2R1/S2R1_H3_neckYaw.dae"/>
      </geometry>
    </visual>
    <collision>
      <origin rpy="0.0 0.0 0.0 " xyz="0 0 0"/>
      <geometry name="S2R1_H3_neckYaw_collision">
        <box size="0.01 0.01 0.01"/>
      </geometry>
    </collision>
  </link>
  <joint name="m3joint_ms2_j3" type="revolute">
    <axis xyz="0 -1 0"/>
    <origin rpy="0 0 0" xyz="0 0 0"/>
    <parent link="neck_yaw"/>
    <child link="head_shell"/>
    <limit effort="100" lower="-0.123429684701" upper="0.647028460299" velocity="0.872664625997"/>
  </joint>
  <link name="head_shell">
    <inertial>
      <mass value="3.178"/>
      <origin xyz="0.034944 0.000563 0.058668"/>
      <inertia ixx="0.022924" ixy="-0.000034" ixz="-0.002929" iyy="0.021814" iyz="-0.000235" izz="0.026783"/>
    </inertial>
    <visual>
      <material name="GreyA"/>
      <origin rpy="0 0 0 " xyz="0 0 0"/>
      <geometry name="head_shell_geom">
        <mesh filename="package://meka_description/meshes/mid_res/S2R1/S2R1_H4_UTA_head.dae"/>
      </geometry>
    </visual>
    <collision>
      <origin rpy="0.0 0.0 0.0 " xyz="0 0 0"/>
      <geometry name="head_shell_collision">
        <mesh filename="package://meka_description/meshes/low_res/S2R1/S2R1_H4_UTA_head.stl"/>
      </geometry>
    </collision>
  </link>
  <joint name="m3joint_ms2_j4" type="revolute">
    <axis xyz="0 -1 0"/>
    <limit effort="100" lower="-0.610690705273" upper="0.610690705273" velocity="27.9252680319"/>
    <origin rpy="0 0 0" xyz="0.12508 0 0"/>
    <parent link="head_shell"/>
    <child link="eye_tilt"/>
  </joint>
  <link name="eye_tilt">
    <visual>
      <material name="GreyC"/>
      <origin rpy="0 0 0 " xyz="0 0 0"/>
      <geometry name="eye_tilt_geom">
        <mesh filename="package://meka_description/meshes/mid_res/S2R1/S2R1_SH5_eyeTilt.dae"/>
      </geometry>
    </visual>
    <collision>
      <origin rpy="0.0 0.0 0.0 " xyz="0 0 0"/>
      <geometry name="eye_tilt_collision">
        <box size="0.01 0.01 0.01"/>
      </geometry>
    </collision>
  </link>
  <joint name="m3joint_ms2_j5" type="revolute">
    <axis xyz="0 0 1"/>
    <limit effort="100" lower="-0.597077137107" upper="0.597129496985" velocity="27.9252680319"/>
    <origin rpy="0 0 0" xyz="0 -0.053 0"/>
    <parent link="eye_tilt"/>
    <child link="right_eye"/>
  </joint>
  <link name="right_eye">
    <visual>
      <material name="GreyC"/>
      <origin rpy="0 0 0 " xyz="0 0 0"/>
      <geometry name="right_eye_geom">
        <mesh filename="package://meka_description/meshes/mid_res/S2R1/S2R1_eye.dae"/>
      </geometry>
    </visual>
    <collision>
      <origin rpy="0.0 0.0 0.0 " xyz="0 0 0"/>
      <geometry name="right_eye_collision">
        <mesh filename="package://meka_description/meshes/low_res/S2R1/S2R1_eye.stl"/>
      </geometry>
    </collision>
  </link>
  <joint name="m3joint_ms2_j6" type="revolute">
    <axis xyz="0 0 1"/>
    <limit effort="100" lower="-0.6129596333" upper="0.613046899763" velocity="27.9252680319"/>
    <origin rpy="0 0 0" xyz="0 0.053 0"/>
    <parent link="eye_tilt"/>
    <child link="left_eye"/>
  </joint>
  <link name="left_eye">
    <visual>
      <material name="GreyC"/>
      <origin rpy="0 0 0 " xyz="0 0 0"/>
      <geometry name="left_eye_geom">
        <mesh filename="package://meka_description/meshes/mid_res/S2R1/S2R1_eye.dae"/>
      </geometry>
    </visual>
    <collision>
      <origin rpy="0.0 0.0 0.0 " xyz="0 0 0"/>
      <geometry name="left_eye_collision">
        <mesh filename="package://meka_description/meshes/low_res/S2R1/S2R1_eye.stl"/>
      </geometry>
    </collision>
  </link>
  <joint name="palm_joint" type="fixed">
    <origin rpy="0 0 0" xyz="0 0 -0.04414"/>
    <parent link="handmount_RIGHT"/>
    <child link="palm"/>
  </joint>
  <link name="palm">
    <inertial>
      <mass value="0.663"/>
      <origin xyz="0.001459 0.001619 -0.051312"/>
      <inertia ixx="0.000873" ixy="0.000031" ixz="-0.000008" iyy="0.000597" iyz="0.000016" izz="0.000565"/>
    </inertial>
    <visual>
      <material name="GreyA"/>
      <origin rpy="0 0 0 " xyz="0 0 0"/>
      <geometry name="palm_geom">
        <mesh filename="package://meka_description/meshes/mid_res/H2R3/H2R3_RT8_palm_right.dae"/>
      </geometry>
    </visual>
    <collision>
      <origin rpy="0.0 0.0 0.0 " xyz="0 0 0"/>
      <geometry name="palm_collision">
        <mesh filename="package://meka_description/meshes/low_res/H2R3/H2R3_RT8_palm_right.stl"/>
      </geometry>
    </collision>
  </link>
  <joint name="m3joint_ua_mh8_j0" type="revolute">
    <axis xyz="0 0 -1"/>
    <origin rpy="0 0 0" xyz="-0.02 0.028 -0.03"/>
    <parent link="palm"/>
    <child link="thumb0"/>
    <limit effort="100" lower="-0.698131700798" upper="0.261799387799" velocity="0.349065850399"/>
  </joint>
  <link name="thumb0">
    <inertial>
      <mass value="0.0117"/>
      <origin xyz="0.0 0.0 0.0"/>
      <inertia ixx="0.0" ixy="0.0" ixz="0.0" iyy="0.0" iyz="0.0" izz="0.0"/>
    </inertial>
    <visual>
      <material name="GreyA"/>
      <origin rpy="0 0 0 " xyz="0 0 0"/>
      <geometry name="thumb0_geom">
        <mesh filename="package://meka_description/meshes/mid_res/H2R3/H2R3_RJ0_thumb_abductlink.dae"/>
      </geometry>
    </visual>
    <collision>
      <origin rpy="0.0 0.0 0.0 " xyz="0 0 0"/>
      <geometry name="thumb0_collision">
        <mesh filename="package://meka_description/meshes/low_res/H2R3/H2R3_RJ0_thumb_abductlink.stl"/>
      </geometry>
    </collision>
  </link>
  <joint name="m3joint_ua_mh8_j1" type="revolute">
    <axis xyz="0 -1 0"/>
    <limit effort="100" lower="-1.41230297742" upper="1.41214589779" velocity="1.308996939"/>
    <origin rpy="0 0 0" xyz="-0.018 0 0"/>
    <parent link="thumb0"/>
    <child link="thumb1"/>
  </joint>
  <link name="thumb1">
    <inertial>
      <mass value="0.0344"/>
      <origin xyz="0.0 0.0 0.0"/>
      <inertia ixx="0.0" ixy="0.0" ixz="0.0" iyy="0.0" iyz="0.0" izz="0.0"/>
    </inertial>
    <visual>
      <material name="GreyB"/>
      <origin rpy="0 0 0 " xyz="0 0 0"/>
      <geometry name="thumb1_geom">
        <mesh filename="package://meka_description/meshes/mid_res/H2R3/H2R3_thumb_knuckle1.dae"/>
      </geometry>
    </visual>
    <collision>
      <origin rpy="0.0 0.0 0.0 " xyz="0 0 0"/>
      <geometry name="thumb1_collision">
        <mesh filename="package://meka_description/meshes/low_res/H2R3/H2R3_thumb_knuckle1.stl"/>
      </geometry>
    </collision>
  </link>
  <joint name="m3joint_ua_mh8_j2" type="revolute">
    <axis xyz="0 -1 0"/>
    <origin rpy="0 0 0" xyz="-0.044 0 0"/>
    <parent link="thumb1"/>
    <child link="thumb2"/>
    <limit effort="100" lower="-0.260752190248" upper="0.260752190248" velocity="0.872664625997"/>
  </joint>
  <link name="thumb2">
    <inertial>
      <mass value="0.01"/>
      <origin xyz="0.0 0.0 0.0"/>
      <inertia ixx="0.0" ixy="0.0" ixz="0.0" iyy="0.0" iyz="0.0" izz="0.0"/>
    </inertial>
    <visual>
      <material name="GreyC"/>
      <origin rpy="0 0 0 " xyz="0 0 0"/>
      <geometry name="thumb_knuckle2_geom">
        <mesh filename="package://meka_description/meshes/mid_res/H2R3/H2R3_thumb_knuckle2.dae"/>
      </geometry>
    </visual>
    <collision>
      <origin rpy="0.0 0.0 0.0 " xyz="0 0 0"/>
      <geometry name="thumb_knuckle2_collision">
        <mesh filename="package://meka_description/meshes/low_res/H2R3/H2R3_thumb_knuckle2.stl"/>
      </geometry>
    </collision>
  </link>
  <joint name="m3joint_ua_mh8_j3" type="revolute">
    <axis xyz="0 1 0"/>
    <origin rpy="0 0 0" xyz="0 0.028 -0.101"/>
    <parent link="palm"/>
    <child link="index0"/>
    <limit effort="100" lower="-0.123429684701" upper="0.647028460299" velocity="0.872664625997"/>
  </joint>
  <link name="index0">
    <inertial>
      <mass value="0.01"/>
      <origin xyz="0.0 0.0 0.0"/>
      <inertia ixx="0.0" ixy="0.0" ixz="0.0" iyy="0.0" iyz="0.0" izz="0.0"/>
    </inertial>
    <visual>
      <material name="GreyA"/>
      <origin rpy="0 0 0 " xyz="0 0 0"/>
      <geometry name="index0_geom">
        <mesh filename="package://meka_description/meshes/mid_res/H2R3/H2R3_finger_knuckle1.dae"/>
      </geometry>
    </visual>
    <collision>
      <origin rpy="0.0 0.0 0.0 " xyz="0 0 0"/>
      <geometry name="index0__collision">
        <mesh filename="package://meka_description/meshes/low_res/H2R3/H2R3_finger_knuckle1.stl"/>
      </geometry>
    </collision>
  </link>
  <joint name="m3joint_ua_mh8_j4" type="revolute">
    <axis xyz="0 1 0"/>
    <limit effort="100" lower="-0.610690705273" upper="0.610690705273" velocity="27.9252680319"/>
    <origin rpy="0 0 0" xyz="0 0 -0.044"/>
    <parent link="index0"/>
    <child link="index1"/>
  </joint>
  <link name="index1">
    <inertial>
      <mass value="0.0429"/>
      <origin xyz="0.0 0.0 0.0"/>
      <inertia ixx="0.0" ixy="0.0" ixz="0.0" iyy="0.0" iyz="0.0" izz="0.0"/>
    </inertial>
    <visual>
      <material name="GreyC"/>
      <origin rpy="0 0 0 " xyz="0 0 0"/>
      <geometry name="index1_geom">
        <mesh filename="package://meka_description/meshes/mid_res/H2R3/H2R3_finger_knuckle2.dae"/>
      </geometry>
    </visual>
    <collision>
      <origin rpy="0.0 0.0 0.0 " xyz="0 0 0"/>
      <geometry name="index1_collision">
        <mesh filename="package://meka_description/meshes/low_res/H2R3/H2R3_finger_knuckle2.stl"/>
      </geometry>
    </collision>
  </link>
  <joint name="m3joint_ua_mh8_j5" type="revolute">
    <axis xyz="0 1 0"/>
    <limit effort="100" lower="-0.597077137107" upper="0.597129496985" velocity="27.9252680319"/>
    <origin rpy="0 0 0" xyz="0 0 -0.032"/>
    <parent link="index1"/>
    <child link="index2"/>
  </joint>
  <link name="index2">
    <inertial>
      <mass value="0.01"/>
      <origin xyz="0.0 0.0 0.0"/>
      <inertia ixx="0.0" ixy="0.0" ixz="0.0" iyy="0.0" iyz="0.0" izz="0.0"/>
    </inertial>
    <visual>
      <material name="GreyC"/>
      <origin rpy="0 0 0 " xyz="0 0 0"/>
      <geometry name="index2_geom">
        <mesh filename="package://meka_description/meshes/mid_res/H2R3/H2R3_finger_knuckle3.dae"/>
      </geometry>
    </visual>
    <collision>
      <origin rpy="0.0 0.0 0.0 " xyz="0 0 0"/>
      <geometry name="index2_collision">
        <mesh filename="package://meka_description/meshes/low_res/H2R3/H2R3_finger_knuckle3.stl"/>
      </geometry>
    </collision>
  </link>
  <joint name="m3joint_ua_mh8_j6" type="revolute">
    <axis xyz="0 1 0"/>
    <origin rpy="0 0 0" xyz="0 0 -0.101"/>
    <parent link="palm"/>
    <child link="ring0"/>
    <limit effort="100" lower="-0.123429684701" upper="0.647028460299" velocity="0.872664625997"/>
  </joint>
  <link name="ring0">
    <inertial>
      <mass value="0.01"/>
      <origin xyz="0.0 0.0 0.0"/>
      <inertia ixx="0.0" ixy="0.0" ixz="0.0" iyy="0.0" iyz="0.0" izz="0.0"/>
    </inertial>
    <visual>
      <material name="GreyA"/>
      <origin rpy="0 0 0 " xyz="0 0 0"/>
      <geometry name="ring0_geom">
        <mesh filename="package://meka_description/meshes/mid_res/H2R3/H2R3_finger_knuckle1.dae"/>
      </geometry>
    </visual>
    <collision>
      <origin rpy="0.0 0.0 0.0 " xyz="0 0 0"/>
      <geometry name="ring0__collision">
        <mesh filename="package://meka_description/meshes/low_res/H2R3/H2R3_finger_knuckle1.stl"/>
      </geometry>
    </collision>
  </link>
  <joint name="m3joint_ua_mh8_j7" type="revolute">
    <axis xyz="0 1 0"/>
    <limit effort="100" lower="-0.610690705273" upper="0.610690705273" velocity="27.9252680319"/>
    <origin rpy="0 0 0" xyz="0 0 -0.044"/>
    <parent link="ring0"/>
    <child link="ring1"/>
  </joint>
  <link name="ring1">
    <inertial>
      <mass value="0.0429"/>
      <origin xyz="0.0 0.0 0.0"/>
      <inertia ixx="0.0" ixy="0.0" ixz="0.0" iyy="0.0" iyz="0.0" izz="0.0"/>
    </inertial>
    <visual>
      <material name="GreyC"/>
      <origin rpy="0 0 0 " xyz="0 0 0"/>
      <geometry name="ring1_geom">
        <mesh filename="package://meka_description/meshes/mid_res/H2R3/H2R3_finger_knuckle2.dae"/>
      </geometry>
    </visual>
    <collision>
      <origin rpy="0.0 0.0 0.0 " xyz="0 0 0"/>
      <geometry name="ring1_collision">
        <mesh filename="package://meka_description/meshes/low_res/H2R3/H2R3_finger_knuckle2.stl"/>
      </geometry>
    </collision>
  </link>
  <joint name="m3joint_ua_mh8_j8" type="revolute">
    <axis xyz="0 1 0"/>
    <limit effort="100" lower="-0.597077137107" upper="0.597129496985" velocity="27.9252680319"/>
    <origin rpy="0 0 0" xyz="0 0 -0.032"/>
    <parent link="ring1"/>
    <child link="ring2"/>
  </joint>
  <link name="ring2">
    <inertial>
      <mass value="0.01"/>
      <origin xyz="0.0 0.0 0.0"/>
      <inertia ixx="0.0" ixy="0.0" ixz="0.0" iyy="0.0" iyz="0.0" izz="0.0"/>
    </inertial>
    <visual>
      <material name="GreyC"/>
      <origin rpy="0 0 0 " xyz="0 0 0"/>
      <geometry name="ring2_geom">
        <mesh filename="package://meka_description/meshes/mid_res/H2R3/H2R3_finger_knuckle3.dae"/>
      </geometry>
    </visual>
    <collision>
      <origin rpy="0.0 0.0 0.0 " xyz="0 0 0"/>
      <geometry name="ring2_collision">
        <mesh filename="package://meka_description/meshes/low_res/H2R3/H2R3_finger_knuckle3.stl"/>
      </geometry>
    </collision>
  </link>
  <joint name="m3joint_ua_mh8_j9" type="revolute">
    <axis xyz="0 1 0"/>
    <origin rpy="0 0 0" xyz="0 -0.028 -0.101"/>
    <parent link="palm"/>
    <child link="pinky0"/>
    <limit effort="100" lower="-0.123429684701" upper="0.647028460299" velocity="0.872664625997"/>
  </joint>
  <link name="pinky0">
    <inertial>
      <mass value="0.01"/>
      <origin xyz="0.0 0.0 0.0"/>
      <inertia ixx="0.0" ixy="0.0" ixz="0.0" iyy="0.0" iyz="0.0" izz="0.0"/>
    </inertial>
    <visual>
      <material name="GreyA"/>
      <origin rpy="0 0 0 " xyz="0 0 0"/>
      <geometry name="pinky0_geom">
        <mesh filename="package://meka_description/meshes/mid_res/H2R3/H2R3_finger_knuckle1.dae"/>
      </geometry>
    </visual>
    <collision>
      <origin rpy="0.0 0.0 0.0 " xyz="0 0 0"/>
      <geometry name="pinky0__collision">
        <mesh filename="package://meka_description/meshes/low_res/H2R3/H2R3_finger_knuckle1.stl"/>
      </geometry>
    </collision>
  </link>
  <joint name="m3joint_ua_mh8_j10" type="revolute">
    <axis xyz="0 1 0"/>
    <limit effort="100" lower="-0.610690705273" upper="0.610690705273" velocity="27.9252680319"/>
    <origin rpy="0 0 0" xyz="0 0 -0.044"/>
    <parent link="pinky0"/>
    <child link="pinky1"/>
  </joint>
  <link name="pinky1">
    <inertial>
      <mass value="0.0429"/>
      <origin xyz="0.0 0.0 0.0"/>
      <inertia ixx="0.0" ixy="0.0" ixz="0.0" iyy="0.0" iyz="0.0" izz="0.0"/>
    </inertial>
    <visual>
      <material name="GreyC"/>
      <origin rpy="0 0 0 " xyz="0 0 0"/>
      <geometry name="pinky1_geom">
        <mesh filename="package://meka_description/meshes/mid_res/H2R3/H2R3_finger_knuckle2.dae"/>
      </geometry>
    </visual>
    <collision>
      <origin rpy="0.0 0.0 0.0 " xyz="0 0 0"/>
      <geometry name="pinky1_collision">
        <mesh filename="package://meka_description/meshes/low_res/H2R3/H2R3_finger_knuckle2.stl"/>
      </geometry>
    </collision>
  </link>
  <joint name="m3joint_ua_mh8_j11" type="revolute">
    <axis xyz="0 1 0"/>
    <limit effort="100" lower="-0.597077137107" upper="0.597129496985" velocity="27.9252680319"/>
    <origin rpy="0 0 0" xyz="0 0 -0.032"/>
    <parent link="pinky1"/>
    <child link="pinky2"/>
  </joint>
  <link name="pinky2">
    <inertial>
      <mass value="0.01"/>
      <origin xyz="0.0 0.0 0.0"/>
      <inertia ixx="0.0" ixy="0.0" ixz="0.0" iyy="0.0" iyz="0.0" izz="0.0"/>
    </inertial>
    <visual>
      <material name="GreyC"/>
      <origin rpy="0 0 0 " xyz="0 0 0"/>
      <geometry name="pinky2_geom">
        <mesh filename="package://meka_description/meshes/mid_res/H2R3/H2R3_finger_knuckle3.dae"/>
      </geometry>
    </visual>
    <collision>
      <origin rpy="0.0 0.0 0.0 " xyz="0 0 0"/>
      <geometry name="pinky2_collision">
        <mesh filename="package://meka_description/meshes/low_res/H2R3/H2R3_finger_knuckle3.stl"/>
      </geometry>
    </collision>
  </link>
  <!--<m3_l_arm side="l" reflect="1" parent="upper">
    <origin xyz="0.0 0.18465 0.2337" rpy="0 0 0" />
  </m3_l_arm>-->
  <link name="world"/>
  <!-- Solid Base -->
  <joint name="base_joint" type="fixed">
    <origin rpy="0 0 0" xyz="0 0 1"/>
    <parent link="world"/>
    <child link="panplate"/>
    <dynamics damping="1.0"/>
  </joint>
  <link name="panplate">
    <inertial>
      <mass value="1000"/>
      <origin xyz="0 0 0"/>
      <inertia ixx="100" ixy="0" ixz="0" iyy="100" iyz="0" izz="100"/>
    </inertial>
    <visual>
      <material name="GreyA"/>
      <origin rpy="0 0 0 " xyz="0 0 0"/>
      <geometry name="panplate_geom">
        <mesh filename="package://meka_description/meshes/mid_res/T2R3/T2R3_TJ0_base.dae"/>
      </geometry>
    </visual>
    <collision>
      <origin rpy="0.0 0.0 0.0 " xyz="0 0 0"/>
      <geometry name="base_collision_geom">
        <mesh filename="package://meka_description/meshes/low_res/T2R3/T2R3_TJ0_base.stl"/>
      </geometry>
    </collision>
  </link>
  <joint name="m3joint_mt3_j0" type="continuous">
    <axis xyz="0 0 1"/>
    <origin rpy="0 0 0" xyz="0 0 0.1678"/>
    <parent link="panplate"/>
    <child link="torso"/>
    <limit effort="25" lower="-2.09439510239" upper="2.09439510239" velocity="0.436332312999"/>
    <dynamics damping="1.0"/>
  </joint>
  <link name="torso">
    <inertial>
      <mass value="4.411"/>
      <origin xyz="0.00011774 0.0038073 -0.0522753"/>
      <inertia ixx="0.026360" ixy="-0.0000024" ixz="-0.0000508" iyy="0.0134266" iyz="0.0006839" izz="0.0229879"/>
    </inertial>
    <visual>
      <material name="GreyC"/>
      <origin rpy="0 0 0 " xyz="0 0 0"/>
      <geometry name="torso_geom">
        <mesh filename="package://meka_description/meshes/mid_res/T2R3/T2R3_TJ1_pan.dae"/>
      </geometry>
    </visual>
    <collision>
      <origin rpy="0.0 0.0 0.0 " xyz="0 0 0"/>
      <geometry name="torso_collision_geom">
        <mesh filename="package://meka_description/meshes/low_res/T2R3/T2R3_TJ1_pan.stl"/>
      </geometry>
    </collision>
  </link>
  <joint name="m3joint_mt3_j1" type="continuous">
    <axis xyz="0 1 0"/>
    <origin rpy="0 0 0" xyz="0 0 0"/>
    <parent link="torso"/>
    <child link="mid"/>
    <limit effort="200" lower="-0.205835230801" upper="0.930146870379" velocity="0.174532925199"/>
    <dynamics damping="1.0"/>
  </joint>
  <link name="mid">
    <inertial>
      <mass value="4.934"/>
      <origin xyz="0.001179 -0.002993 0.046259"/>
      <inertia ixx="0.041106" ixy="0.000135" ixz="0.000505" iyy="0.026009" iyz="0.002396" izz="0.025902"/>
    </inertial>
    <visual>
      <material name="GreyB"/>
      <origin rpy="0 0 0" xyz="0 0 0"/>
      <geometry name="mid_geom">
        <mesh filename="package://meka_description/meshes/mid_res/T2R3/T2R3_TJ2.dae"/>
      </geometry>
    </visual>
    <collision>
      <origin rpy="0.0 0.0 0.0 " xyz="0 0 0"/>
      <geometry name="mid_collision_geom">
        <mesh filename="package://meka_description/meshes/low_res/T2R3/T2R3_TJ2.stl"/>
      </geometry>
    </collision>
  </link>
  <joint name="m3joint_slave_mt3_j2" type="continuous">
    <axis xyz="0 1 0"/>
    <origin rpy="0 0 0" xyz="0 0 0.1397"/>
    <parent link="mid"/>
    <child link="upper"/>
    <limit effort="200" lower="-0.205835230801" upper="0.930146870379" velocity="0.174532925199"/>
    <dynamics damping="1.0"/>
  </joint>
  <link name="upper">
    <inertial>
      <mass value="6.534"/>
      <!-- torso with motors, bottom pullies, and neck mount -->
      <origin xyz="0.008700 0.011470 0.129740"/>
      <inertia ixx="0.069760" ixy="-0.000400" ixz="0.001300" iyy="0.048010" iyz="0.005100" izz="0.040590"/>
    </inertial>
    <visual>
      <material name="GreyC"/>
      <origin rpy="0 0 0" xyz="0 0 0"/>
      <geometry name="upper_geom">
        <mesh filename="package://meka_description/meshes/mid_res/T2R3/T2R3_TJ3_chest_waist_neck.dae"/>
      </geometry>
    </visual>
    <collision>
      <origin rpy="0.0 0.0 0.0 " xyz="0 0 0"/>
      <geometry name="upper_collision_geom">
        <mesh filename="package://meka_description/meshes/low_res/T2R3/T2R3_TJ3_chest_waist_neck.stl"/>
      </geometry>
    </collision>
  </link>
</robot>

