<?xml version="1.0"?>
<robot xmlns:sensor="http://playerstage.sourceforge.net/gazebo/xmlschema/#sensor"
       xmlns:controller="http://playerstage.sourceforge.net/gazebo/xmlschema/#controller"
       xmlns:interface="http://playerstage.sourceforge.net/gazebo/xmlschema/#interface"
       xmlns:xacro="http://playerstage.sourceforge.net/gazebo/xmlschema/#interface"
       name="uta" >

 <property name="M_PI" value="3.1415926535897931" />
 <property name="R_ARM" value="ma10" />
 <property name="R_HAND" value="mh8" />
 <property name="TORSO" value="mt3" />
 <property name="HEAD" value="ms2" />
 <property name="MESH" value="meka_description/meshes/mid_res" />
 <property name="MESH_COLL" value="meka_description/meshes/low_res" />

<!-- generic simulator_gazebo plugins for starting mechanism control, ros time, ros battery -->
  <include filename="$(find meka_description)/gazebo/gazebo.urdf.xacro" />
  <include filename="$(find meka_description)/transmissions/uta.transmission.xacro" />

<!-- Meka Arm -->
  <include filename="$(find meka_description)/urdf/A2R3_r_arm_defs.urdf.xacro" />
<!-- Meka Hand -->
  <include filename="$(find meka_description)/urdf/H2R2_r_hand_defs.urdf.xacro" />
<!-- Meka Head -->
  <include filename="$(find meka_description)/urdf/S2R1_head_defs.urdf.xacro" />


  <!-- john added transmissions -->
  <include filename="$(find meka_description)/transmissions/A2R3_r_arm_defs.transmission.xacro" />
  <include filename="$(find meka_description)/transmissions/H2R2_r_hand_defs.transmission.xacro" />
  <include filename="$(find meka_description)/transmissions/S2R1_head_defs.transmission.xacro" />


   <property name="M_PI" value="3.1415926535897931" />
  <material name="GreyA"> <!-- darkest -->
    <color rgba="0.3 0.3 0.3 1.0"/>
  </material>
  
  <material name="GreyB">
    <color rgba="0.5 0.5 0.5 1.0"/>
  </material>
  
  <material name="GreyC">
    <color rgba="0.7 0.7 0.7 1.0"/>
  </material>
  
 <m3_r_arm side="r" reflect="1" parent="upper">
    <origin xyz="0.0 -0.18465 0.2337" rpy="0 0 0" />
  </m3_r_arm>

  <!-- john added transmissions -->
  <m3_r_arm_transmission side="r" reflect="1" parent="upper"/>
  <m3_r_hand_transmission/>
  <m3_head_transmission/>
  
  <m3_head side="r" reflect="1" parent="upper">
    <origin xyz="0.0 0.0 0.31155" rpy="0 0 0" />
  </m3_head>

  <m3_r_hand side="r" reflect="1" parent="handmount_RIGHT">
    <origin xyz="0.0 0.0 0.0" rpy="0 0 0" />
  </m3_r_hand>
  
  <!--<m3_l_arm side="l" reflect="1" parent="upper">
    <origin xyz="0.0 0.18465 0.2337" rpy="0 0 0" />
  </m3_l_arm>-->
  



  <link name="world" />
  
  <!-- Solid Base -->
  <joint name="base_joint" type="fixed">
    <origin xyz="0 0 1" rpy="0 0 0" />
    <parent link="world" />
    <child link="panplate" />
    <dynamics damping="1.0"/>
  </joint>
  <link name="panplate">
    <inertial>
      <mass value="1000" />
      <origin xyz="0 0 0" />
      <inertia ixx="100"  ixy="0"  ixz="0" iyy="100" iyz="0" izz="100" />
    </inertial>
    <visual>
      <material name="GreyA" />
      <origin xyz="0 0 0" rpy="0 0 0 " />
      <geometry name="panplate_geom">
        <mesh filename="package://${MESH}/T2R3/T2R3_TJ0_base.dae" />
      </geometry>  
    </visual>     
    <collision>
      <origin xyz="0 0 0" rpy="0.0 0.0 0.0 " />
      <geometry name="base_collision_geom">
        <mesh filename="package://${MESH_COLL}/T2R3/T2R3_TJ0_base.stl" />
      </geometry>
    </collision>
  </link>
  <joint name="m3joint_${TORSO}_j0" type="continuous">
    <axis xyz="0 0 1"/>
    <origin xyz="0 0 0.1678" rpy="0 0 0" />
    <parent link="panplate" />
    <child link="torso" />
    <limit effort="25" velocity="${25.0*M_PI/180}" lower="${-120*M_PI/180.0}" upper="${120*M_PI/180}" />
    <dynamics damping="1.0"/>
  </joint>
  <link name="torso">
    <inertial>
      <mass value="4.411" />
      <origin xyz="0.00011774 0.0038073 -0.0522753" />
      <inertia ixx="0.026360"  ixy="-0.0000024"  ixz="-0.0000508" iyy="0.0134266" iyz="0.0006839" izz="0.0229879" />
    </inertial>
    <visual>
      <material name="GreyC" />
      <origin xyz="0 0 0" rpy="0 0 0 " />
      <geometry name="torso_geom">
        <mesh filename="package://${MESH}/T2R3/T2R3_TJ1_pan.dae" />
      </geometry>  
    </visual>
    <collision>
      <origin xyz="0 0 0" rpy="0.0 0.0 0.0 " />
      <geometry name="torso_collision_geom">
        <mesh filename="package://${MESH_COLL}/T2R3/T2R3_TJ1_pan.stl" />
      </geometry>
    </collision>
  </link>
  
  <joint name="m3joint_${TORSO}_j1" type="continuous">
    <axis xyz="0 1 0"/>
    <origin xyz="0 0 0" rpy="0 0 0" />    
    <parent link="torso" />
    <child link="mid" />
    <limit effort="200" velocity="${10.0*M_PI/180}" lower="${-11.79349*M_PI/180}" upper="${53.29349*M_PI/180}" />
    <dynamics damping="1.0"/>
  </joint>
  <link name="mid">
    <inertial>
      <mass value="4.934" />
      <origin xyz="0.001179 -0.002993 0.046259"/>
      <inertia ixx="0.041106"
      iyy="0.026009"
      izz="0.025902"
      ixy="0.000135"
      ixz="0.000505"
      iyz="0.002396" />
    </inertial>
    <visual>
      <material name="GreyB" />
      <origin xyz="0 0 0" rpy="0 0 0" />
      <geometry name="mid_geom">
        <mesh filename="package://${MESH}/T2R3/T2R3_TJ2.dae" />
      </geometry>
    </visual>
    <collision>
      <origin xyz="0 0 0" rpy="0.0 0.0 0.0 " />
      <geometry name="mid_collision_geom">
        <mesh filename="package://${MESH_COLL}/T2R3/T2R3_TJ2.stl" />
      </geometry>
    </collision>
  </link>
  
  <joint name="m3joint_slave_${TORSO}_j2" type="continuous">
    <axis xyz="0 1 0"/>
    <origin xyz="0 0 0.1397" rpy="0 0 0" />    
    <parent link="mid" />
    <child link="upper" />
    <limit effort="200" velocity="${10.0*M_PI/180}" lower="${-11.79349*M_PI/180}" upper="${53.29349*M_PI/180}" />
    <dynamics damping="1.0"/>
  </joint>

  <link name="upper">
    <inertial>
      <mass value="6.534" /> <!-- torso with motors, bottom pullies, and neck mount -->
      <origin xyz="0.008700 0.011470 0.129740"/>
      <inertia ixx="0.069760"
      iyy="0.048010"
      izz="0.040590"
      ixy="-0.000400"
      ixz="0.001300"
      iyz="0.005100" />
    </inertial>
    <visual>
      <material name="GreyC" />
      <origin xyz="0 0 0" rpy="0 0 0" />
      <geometry name="upper_geom">
        <mesh filename="package://${MESH}/T2R3/T2R3_TJ3_chest_waist_neck.dae" />
      </geometry>
    </visual>
    <collision>
      <origin xyz="0 0 0" rpy="0.0 0.0 0.0 " />
      <geometry name="upper_collision_geom">
        <mesh filename="package://${MESH_COLL}/T2R3/T2R3_TJ3_chest_waist_neck.stl" />
      </geometry>
    </collision>
  </link>

</robot>
  
